<?xml version="1.0" ?>
<!-- =================================================================================== -->
<!-- |    This document was autogenerated by xacro from moritz_robot_yaml/robot.urdf.xacro | -->
<!-- |    EDITING THIS FILE BY HAND IS NOT RECOMMENDED                                 | -->
<!-- =================================================================================== -->
<robot name="r100-0138" xmlns:ignition="http://gazebosim.org/schema">
  <material name="clearpath_dark_grey">
    <color rgba="0.2 0.2 0.2 1.0"/>
  </material>
  <material name="clearpath_medium_grey">
    <color rgba="0.6 0.6 0.6 1.0"/>
  </material>
  <material name="clearpath_light_grey">
    <color rgba="0.8 0.8 0.8 1.0"/>
  </material>
  <material name="clearpath_yellow">
    <color rgba="0.8 0.8 0.0 1.0"/>
  </material>
  <material name="clearpath_black">
    <color rgba="0.15 0.15 0.15 1.0"/>
  </material>
  <material name="clearpath_white">
    <color rgba="1.0 1.0 1.0 1.0"/>
  </material>
  <material name="clearpath_red">
    <color rgba="1.0 0.0 0.0 1.0"/>
  </material>
  <material name="clearpath_aluminum">
    <color rgba="0.5 0.5 0.5 1"/>
  </material>
  <material name="clearpath_plastic">
    <color rgba="0.1 0.1 0.1   1"/>
  </material>
  <!-- Chassis -->
  <link name="base_link"/>
  <joint name="base_link_joint" type="fixed">
    <origin rpy="0 0 0" xyz="0 0 0"/>
    <parent link="base_link"/>
    <child link="chassis_link"/>
  </joint>
  <link name="chassis_link">
    <visual>
      <origin rpy="0 0 0" xyz="0 0 0"/>
      <geometry>
        <mesh filename="package://mm_3d_model_detached/meshes/clearpath/body.stl"/>
      </geometry>
      <material name="clearpath_black"/>
    </visual>
    <collision>
      <origin xyz="0 0 0"/>
      <geometry>
        <mesh filename="package://mm_3d_model_detached/meshes/clearpath/body-collision.stl"/>
      </geometry>
    </collision>
    <inertial>
      <origin rpy="1.5707963267948966 0 1.5707963267948966" xyz="0.012 0.002 0.067"/>
      <mass value="165.304"/>
      <inertia ixx="4.4744" ixy="0.03098" ixz="0.003647" iyy="7.1624" iyz="0.1228" izz="4.6155"/>
    </inertial>
  </link>
  <!-- Covers -->
  <joint name="right_side_cover_link_joint" type="fixed">
    <origin rpy="0 0 0" xyz="0 0 0"/>
    <parent link="chassis_link"/>
    <child link="right_side_cover_link"/>
  </joint>
  <joint name="left_side_cover_link_joint" type="fixed">
    <origin rpy="0 0 0" xyz="0 0 0"/>
    <parent link="chassis_link"/>
    <child link="left_side_cover_link"/>
  </joint>
  <link name="left_side_cover_link">
    <visual>
      <origin rpy="0 0 3.141592653589793" xyz="0 0 0"/>
      <geometry>
        <mesh filename="package://mm_3d_model_detached/meshes/clearpath/side-cover.stl"/>
      </geometry>
      <material name="clearpath_yellow"/>
    </visual>
  </link>
  <link name="right_side_cover_link">
    <visual>
      <origin rpy="0 0 0" xyz="0 0 0"/>
      <geometry>
        <mesh filename="package://mm_3d_model_detached/meshes/clearpath/side-cover.stl"/>
      </geometry>
      <material name="clearpath_yellow"/>
    </visual>
  </link>
  <joint name="front_cover_link_joint" type="fixed">
    <origin rpy="0 0 0" xyz="0 0 0"/>
    <parent link="chassis_link"/>
    <child link="front_cover_link"/>
  </joint>
  <link name="front_cover_link">
    <visual>
      <origin rpy="0 0 0" xyz="0 0 0"/>
      <geometry>
        <mesh filename="package://mm_3d_model_detached/meshes/clearpath/end-cover.stl"/>
      </geometry>
      <material name="clearpath_black"/>
    </visual>
  </link>
  <joint name="rear_cover_link_joint" type="fixed">
    <origin rpy="0 0 0" xyz="0 0 0"/>
    <parent link="chassis_link"/>
    <child link="rear_cover_link"/>
  </joint>
  <link name="rear_cover_link">
    <visual>
      <origin rpy="0 0 3.141592653589793" xyz="0 0 0"/>
      <geometry>
        <mesh filename="package://mm_3d_model_detached/meshes/clearpath/end-cover.stl"/>
      </geometry>
      <material name="clearpath_red"/>
    </visual>
  </link>
  <!-- Ligths -->
  <joint name="front_lights_link_joint" type="fixed">
    <origin rpy="0 0 0" xyz="0 0 0"/>
    <parent link="chassis_link"/>
    <child link="front_lights_link"/>
  </joint>
  <joint name="rear_lights_link_joint" type="fixed">
    <origin rpy="0 0 0" xyz="0 0 0"/>
    <parent link="chassis_link"/>
    <child link="rear_lights_link"/>
  </joint>
  <link name="front_lights_link">
    <visual>
      <origin rpy="0 0 0" xyz="0 0 0"/>
      <geometry>
        <mesh filename="package://mm_3d_model_detached/meshes/clearpath/lights.stl"/>
      </geometry>
      <material name="clearpath_white"/>
    </visual>
  </link>
  <link name="rear_lights_link">
    <visual>
      <origin rpy="0 0 3.141592653589793" xyz="0 0 0"/>
      <geometry>
        <mesh filename="package://mm_3d_model_detached/meshes/clearpath/lights.stl"/>
      </geometry>
      <material name="clearpath_black"/>
    </visual>
  </link>
  <!-- Axle -->
  <joint name="axle_joint" type="fixed">
    <origin rpy="0 0 0" xyz="0 0 0.05"/>
    <parent link="chassis_link"/>
    <child link="axle_link"/>
  </joint>
  <link name="axle_link">
    <visual>
      <origin rpy="0 1.5707963267948966 0" xyz="0 0 0"/>
      <geometry>
        <mesh filename="package://mm_3d_model_detached/meshes/clearpath/axle.stl"/>
      </geometry>
      <material name="clearpath_black"/>
    </visual>
  </link>
  <!-- Riser -->
  <joint name="riser_link_joint" type="fixed">
    <origin rpy="0 0 0" xyz="0 0 0.22"/>
    <parent link="chassis_link"/>
    <child link="riser_link"/>
  </joint>
  <link name="riser_link">
    <visual>
      <origin rpy="0 0 0.7853981633974483" xyz="0 0 0.035"/>
      <geometry>
        <box size="0.493 0.493 0.07"/>
      </geometry>
      <material name="clearpath_light_grey"/>
    </visual>
    <collision>
      <origin rpy="0 0 0.7853981633974483" xyz="0 0 0.035"/>
      <geometry>
        <box size="0.493 0.493 0.07"/>
      </geometry>
    </collision>
  </link>
  <!-- Top Plate -->
  <joint name="top_link_joint" type="fixed">
    <origin rpy="0 0 0" xyz="0 0 -0.20500000000000002"/>
    <parent link="riser_link"/>
    <child link="top_link"/>
  </joint>
  <link name="top_link">
    <visual>
      <origin rpy="0 0 0" xyz="0 0 0"/>
      <geometry>
        <mesh filename="package://mm_3d_model_detached/meshes/clearpath/top.stl"/>
      </geometry>
      <material name="clearpath_black"/>
    </visual>
    <collision>
      <origin rpy="0 0 0" xyz="0 0 0"/>
      <geometry>
        <mesh filename="package://mm_3d_model_detached/meshes/clearpath/top.stl"/>
      </geometry>
    </collision>
  </link>
  <link name="front_rocker_link">
    <visual>
      <origin rpy="1.5707963267948966 0 1.5707963267948966" xyz="0 0 0"/>
      <geometry>
        <mesh filename="package://mm_3d_model_detached/meshes/clearpath/rocker.stl"/>
      </geometry>
      <material name="clearpath_black"/>
    </visual>
    <inertial>
      <origin rpy="1.5707963267948966 0 1.5707963267948966" xyz="0 0 0"/>
      <mass value="10.267"/>
      <inertia ixx="0.0288" ixy="2.20484e-6" ixz="-1.3145e-5" iyy="0.4324" iyz="1.8944e-3" izz="0.4130"/>
    </inertial>
  </link>
  <joint name="front_rocker" type="fixed">
    <parent link="axle_link"/>
    <child link="front_rocker_link"/>
    <origin rpy="0 0 0" xyz="0.319 0 0"/>
    <axis xyz="1 0 0"/>
    <limit effort="0" lower="-0.08726" upper="0.08726" velocity="0"/>
  </joint>
  <link name="front_left_wheel_link">
    <visual>
      <origin rpy="1.5707963267948966 0 0" xyz="0 0 0"/>
      <geometry>
        <mesh filename="package://mm_3d_model_detached/meshes/clearpath/wheels/mecanum.stl"/>
      </geometry>
      <material name="clearpath_black"/>
    </visual>
    <collision>
      <origin rpy="1.5707963267948966 0 0" xyz="0 0 0"/>
      <geometry>
        <cylinder length="0.079" radius="0.0759"/>
      </geometry>
    </collision>
    <inertial>
      <origin rpy="0 0 0" xyz="0 0 0"/>
      <mass value="2.5"/>
      <inertia ixx="0.0049007145833333335" ixy="0" ixz="0" iyy="0.0072010124999999986" iyz="0" izz="0.0049007145833333335"/>
    </inertial>
  </link>
  <gazebo reference="front_left_wheel_link">
    <collision>
      <surface>
        <friction>
          <ode>
            <mu>1.0</mu>
            <mu2>0.0</mu2>
            <fdir1 ignition:expressed_in="base_link">1 -1 0</fdir1>
          </ode>
        </friction>
      </surface>
    </collision>
  </gazebo>
  <joint name="front_left_wheel_joint" type="continuous">
    <parent link="front_rocker_link"/>
    <child link="front_left_wheel_link"/>
    <origin rpy="0 0 0" xyz="0 0.27549999999999997 0"/>
    <axis xyz="0 1 0"/>
  </joint>
  <link name="front_right_wheel_link">
    <visual>
      <origin rpy="1.5707963267948966 0 0" xyz="0 0 0"/>
      <geometry>
        <mesh filename="package://mm_3d_model_detached/meshes/clearpath/wheels/mecanum.stl"/>
      </geometry>
      <material name="clearpath_black"/>
    </visual>
    <collision>
      <origin rpy="1.5707963267948966 0 0" xyz="0 0 0"/>
      <geometry>
        <cylinder length="0.079" radius="0.0759"/>
      </geometry>
    </collision>
    <inertial>
      <origin rpy="0 0 0" xyz="0 0 0"/>
      <mass value="2.5"/>
      <inertia ixx="0.0049007145833333335" ixy="0" ixz="0" iyy="0.0072010124999999986" iyz="0" izz="0.0049007145833333335"/>
    </inertial>
  </link>
  <gazebo reference="front_right_wheel_link">
    <collision>
      <surface>
        <friction>
          <ode>
            <mu>1.0</mu>
            <mu2>0.0</mu2>
            <fdir1 ignition:expressed_in="base_link">1 1 0</fdir1>
          </ode>
        </friction>
      </surface>
    </collision>
  </gazebo>
  <joint name="front_right_wheel_joint" type="continuous">
    <parent link="front_rocker_link"/>
    <child link="front_right_wheel_link"/>
    <origin rpy="0 0 0" xyz="0 -0.27549999999999997 0"/>
    <axis xyz="0 1 0"/>
  </joint>
  <link name="rear_rocker_link">
    <visual>
      <origin rpy="1.5707963267948966 0 1.5707963267948966" xyz="0 0 0"/>
      <geometry>
        <mesh filename="package://mm_3d_model_detached/meshes/clearpath/rocker.stl"/>
      </geometry>
      <material name="clearpath_black"/>
    </visual>
    <inertial>
      <origin rpy="1.5707963267948966 0 1.5707963267948966" xyz="0 0 0"/>
      <mass value="10.267"/>
      <inertia ixx="0.0288" ixy="2.20484e-6" ixz="-1.3145e-5" iyy="0.4324" iyz="1.8944e-3" izz="0.4130"/>
    </inertial>
  </link>
  <joint name="rear_rocker" type="fixed">
    <parent link="axle_link"/>
    <child link="rear_rocker_link"/>
    <origin rpy="0 0 0" xyz="-0.319 0 0"/>
    <axis xyz="1 0 0"/>
    <limit effort="0" velocity="0"/>
  </joint>
  <link name="rear_left_wheel_link">
    <visual>
      <origin rpy="1.5707963267948966 0 0" xyz="0 0 0"/>
      <geometry>
        <mesh filename="package://mm_3d_model_detached/meshes/clearpath/wheels/mecanum.stl"/>
      </geometry>
      <material name="clearpath_black"/>
    </visual>
    <collision>
      <origin rpy="1.5707963267948966 0 0" xyz="0 0 0"/>
      <geometry>
        <cylinder length="0.079" radius="0.0759"/>
      </geometry>
    </collision>
    <inertial>
      <origin rpy="0 0 0" xyz="0 0 0"/>
      <mass value="2.5"/>
      <inertia ixx="0.0049007145833333335" ixy="0" ixz="0" iyy="0.0072010124999999986" iyz="0" izz="0.0049007145833333335"/>
    </inertial>
  </link>
  <gazebo reference="rear_left_wheel_link">
    <collision>
      <surface>
        <friction>
          <ode>
            <mu>1.0</mu>
            <mu2>0.0</mu2>
            <fdir1 ignition:expressed_in="base_link">1 1 0</fdir1>
          </ode>
        </friction>
      </surface>
    </collision>
  </gazebo>
  <joint name="rear_left_wheel_joint" type="continuous">
    <parent link="rear_rocker_link"/>
    <child link="rear_left_wheel_link"/>
    <origin rpy="0 0 0" xyz="0 0.27549999999999997 0"/>
    <axis xyz="0 1 0"/>
  </joint>
  <link name="rear_right_wheel_link">
    <visual>
      <origin rpy="1.5707963267948966 0 0" xyz="0 0 0"/>
      <geometry>
        <mesh filename="package://mm_3d_model_detached/meshes/clearpath/wheels/mecanum.stl"/>
      </geometry>
      <material name="clearpath_black"/>
    </visual>
    <collision>
      <origin rpy="1.5707963267948966 0 0" xyz="0 0 0"/>
      <geometry>
        <cylinder length="0.079" radius="0.0759"/>
      </geometry>
    </collision>
    <inertial>
      <origin rpy="0 0 0" xyz="0 0 0"/>
      <mass value="2.5"/>
      <inertia ixx="0.0049007145833333335" ixy="0" ixz="0" iyy="0.0072010124999999986" iyz="0" izz="0.0049007145833333335"/>
    </inertial>
  </link>
  <gazebo reference="rear_right_wheel_link">
    <collision>
      <surface>
        <friction>
          <ode>
            <mu>1.0</mu>
            <mu2>0.0</mu2>
            <fdir1 ignition:expressed_in="base_link">1 -1 0</fdir1>
          </ode>
        </friction>
      </surface>
    </collision>
  </gazebo>
  <joint name="rear_right_wheel_joint" type="continuous">
    <parent link="rear_rocker_link"/>
    <child link="rear_right_wheel_link"/>
    <origin rpy="0 0 0" xyz="0 -0.27549999999999997 0"/>
    <axis xyz="0 1 0"/>
  </joint>
  <gazebo>
    <plugin filename="libgz-sim-wheel-slip-system.so" name="gz::sim::systems::WheelSlip">
      <wheel link_name="front_left_wheel_link">
        <slip_compliance_lateral>1.0</slip_compliance_lateral>
        <slip_compliance_longitudinal>1.0</slip_compliance_longitudinal>
        <wheel_normal_force>200</wheel_normal_force>
        <wheel_radius>0.0759</wheel_radius>
      </wheel>
      <wheel link_name="front_right_wheel_link">
        <slip_compliance_lateral>1.0</slip_compliance_lateral>
        <slip_compliance_longitudinal>1.0</slip_compliance_longitudinal>
        <wheel_normal_force>200</wheel_normal_force>
        <wheel_radius>0.0759</wheel_radius>
      </wheel>
      <wheel link_name="rear_left_wheel_link">
        <slip_compliance_lateral>1.0</slip_compliance_lateral>
        <slip_compliance_longitudinal>1.0</slip_compliance_longitudinal>
        <wheel_normal_force>200</wheel_normal_force>
        <wheel_radius>0.0759</wheel_radius>
      </wheel>
      <wheel link_name="rear_right_wheel_link">
        <slip_compliance_lateral>1.0</slip_compliance_lateral>
        <slip_compliance_longitudinal>1.0</slip_compliance_longitudinal>
        <wheel_normal_force>200</wheel_normal_force>
        <wheel_radius>0.0759</wheel_radius>
      </wheel>
    </plugin>
  </gazebo>
  <!-- Internal IMU -->
  <link name="imu_0_link">
    <inertial>
      <mass value="0.001"/>
      <origin rpy="0 0 0" xyz="0 0 0"/>
      <inertia ixx="1e-09" ixy="0.0" ixz="0.0" iyy="1e-09" iyz="0.0" izz="1e-09"/>
    </inertial>
  </link>
  <joint name="imu_0_joint" type="fixed">
    <parent link="chassis_link"/>
    <child link="imu_0_link"/>
    <origin rpy="0 0 0" xyz="0.2085 -0.2902 0.1681"/>
  </joint>
  <gazebo reference="imu_0_link">
    <sensor name="imu_0" type="imu">
      <always_on>true</always_on>
      <update_rate>50</update_rate>
      <visualize>true</visualize>
      <gz_frame_id>imu_0_link</gz_frame_id>
    </sensor>
  </gazebo>
  <!-- Mounting Hardpoints -->
  <link name="default_mount"/>
  <joint name="default_mount_joint" type="fixed">
    <parent link="riser_link"/>
    <child link="default_mount"/>
    <origin rpy="0 0 0" xyz="0 0 0.07500000000000001"/>
  </joint>
  <!-- ROS2 controls -->
  <ros2_control name="r100_hardware" type="system">
    <hardware>
      <plugin>clearpath_hardware_interfaces/PumaHardware</plugin>
    </hardware>
    <joint name="front_left_wheel_joint">
      <command_interface name="velocity"/>
      <state_interface name="position"/>
      <state_interface name="velocity"/>
    </joint>
    <joint name="front_right_wheel_joint">
      <command_interface name="velocity"/>
      <state_interface name="position"/>
      <state_interface name="velocity"/>
    </joint>
    <joint name="rear_left_wheel_joint">
      <command_interface name="velocity"/>
      <state_interface name="position"/>
      <state_interface name="velocity"/>
    </joint>
    <joint name="rear_right_wheel_joint">
      <command_interface name="velocity"/>
      <state_interface name="position"/>
      <state_interface name="velocity"/>
    </joint>
  </ros2_control>
  <!-- Attachments -->
  <!-- Links -->
  <link name="arm_0_end_effector_link"/>
  <joint name="arm_0_end_effector_joint" type="fixed">
    <parent link="arm_0_tool0"/>
    <child link="arm_0_end_effector_link"/>
    <origin rpy="0.0 0.0 0.0" xyz="0.0 0.0 0.0"/>
  </joint>
  <!-- Mounts -->
  <!-- Sensors -->
  <link name="lidar2d_0_link">
    <visual>
      <origin rpy="0 0 0" xyz="0 0 0"/>
      <geometry>
        <!-- Origin of this mesh is the base of the bracket. -->
        <mesh filename="package://mm_3d_model_detached/meshes/clearpath/hokuyo_ust.stl"/>
      </geometry>
      <material name="clearpath_dark_grey"/>
    </visual>
  </link>
  <link name="lidar2d_0_laser">
    <inertial>
      <mass value="1.1"/>
      <origin xyz="0 0 0"/>
      <inertia ixx="0.00307156543804" ixy="0.0" ixz="0.0" iyy="0.0031284904152700005" iyz="0.0" izz="0.00196432421427"/>
    </inertial>
  </link>
  <joint name="lidar2d_0_joint" type="fixed">
    <origin rpy="0.0 0.0 0.0" xyz="0.3932 0.0 0.1856"/>
    <parent link="base_link"/>
    <child link="lidar2d_0_link"/>
  </joint>
  <joint name="lidar2d_0_laser_joint" type="fixed">
    <!-- This offset is from the base of the bracket to the LIDAR's focal point. -->
    <origin rpy="0 0 0" xyz="0 0 0.0474"/>
    <parent link="lidar2d_0_link"/>
    <child link="lidar2d_0_laser"/>
  </joint>
  <gazebo reference="lidar2d_0_laser">
    <sensor name="lidar2d_0" type="gpu_lidar">
      <update_rate>40</update_rate>
      <visualize>true</visualize>
      <always_on>true</always_on>
      <gz_frame_id>lidar2d_0_laser</gz_frame_id>
      <topic>/sensors/lidar2d_0/scan</topic>
      <lidar>
        <scan>
          <horizontal>
            <samples>540</samples>
            <resolution>1</resolution>
            <min_angle>-2.356</min_angle>
            <max_angle>2.356</max_angle>
          </horizontal>
          <vertical>
            <samples>1</samples>
            <resolution>1</resolution>
            <min_angle>0</min_angle>
            <max_angle>0</max_angle>
          </vertical>
        </scan>
        <range>
          <min>0.05</min>
          <max>25.0</max>
          <resolution>0.01</resolution>
        </range>
      </lidar>
    </sensor>
  </gazebo>
  <link name="lidar2d_1_link">
    <visual>
      <origin rpy="0 0 0" xyz="0 0 0"/>
      <geometry>
        <!-- Origin of this mesh is the base of the bracket. -->
        <mesh filename="package://mm_3d_model_detached/meshes/clearpath/hokuyo_ust.stl"/>
      </geometry>
      <material name="clearpath_dark_grey"/>
    </visual>
  </link>
  <link name="lidar2d_1_laser">
    <inertial>
      <mass value="1.1"/>
      <origin xyz="0 0 0"/>
      <inertia ixx="0.00307156543804" ixy="0.0" ixz="0.0" iyy="0.0031284904152700005" iyz="0.0" izz="0.00196432421427"/>
    </inertial>
  </link>
  <joint name="lidar2d_1_joint" type="fixed">
    <origin rpy="0.0 0.0 3.14159" xyz="-0.3932 0.0 0.1856"/>
    <parent link="base_link"/>
    <child link="lidar2d_1_link"/>
  </joint>
  <joint name="lidar2d_1_laser_joint" type="fixed">
    <!-- This offset is from the base of the bracket to the LIDAR's focal point. -->
    <origin rpy="0 0 0" xyz="0 0 0.0474"/>
    <parent link="lidar2d_1_link"/>
    <child link="lidar2d_1_laser"/>
  </joint>
  <gazebo reference="lidar2d_1_laser">
    <sensor name="lidar2d_1" type="gpu_lidar">
      <update_rate>40</update_rate>
      <visualize>true</visualize>
      <always_on>true</always_on>
      <gz_frame_id>lidar2d_1_laser</gz_frame_id>
      <topic>/sensors/lidar2d_1/scan</topic>
      <lidar>
        <scan>
          <horizontal>
            <samples>540</samples>
            <resolution>1</resolution>
            <min_angle>-2.356</min_angle>
            <max_angle>2.356</max_angle>
          </horizontal>
          <vertical>
            <samples>1</samples>
            <resolution>1</resolution>
            <min_angle>0</min_angle>
            <max_angle>0</max_angle>
          </vertical>
        </scan>
        <range>
          <min>0.05</min>
          <max>25.0</max>
          <resolution>0.01</resolution>
        </range>
      </lidar>
    </sensor>
  </gazebo>
  <!-- Manipulators -->
  <!--
    Base UR robot series xacro macro.

    NOTE this is NOT a URDF. It cannot directly be loaded by consumers
    expecting a flattened '.urdf' file. See the top-level '.xacro' for that
    (but note that .xacro must still be processed by the xacro command).

    This file models the base kinematic chain of a UR robot, which then gets
    parameterised by various configuration files to convert it into a UR3(e),
    UR5(e), UR10(e) or UR16e, etc.

    NOTE the default kinematic parameters (i.e., link lengths, frame locations,
    offsets, etc) do not correspond to any particular robot. They are defaults
    only. There WILL be non-zero offsets between the Forward Kinematics results
    in TF (i.e., robot_state_publisher) and the values reported by the Teach
    Pendant.

    For accurate (and robot-specific) transforms, the 'kinematics_parameters_file'
    parameter MUST point to a .yaml file containing the appropriate values for
    the targeted robot.

    If using the UniversalRobots/Universal_Robots_ROS_Driver, follow the steps
    described in the readme of that repository to extract the kinematic
    calibration from the controller and generate the required .yaml file.

    Main author of the migration to yaml configs Ludovic Delval.

    Contributors to previous versions (in no particular order)

     - Denis Stogl
     - Lovro Ivanov
     - Felix Messmer
     - Kelsey Hawkins
     - Wim Meeussen
     - Shaun Edwards
     - Nadia Hammoudeh Garcia
     - Dave Hershberger
     - G. vd. Hoorn
     - Philip Long
     - Dave Coleman
     - Miguel Prada
     - Mathias Luedtke
     - Marcel Schnirring
     - Felix von Drigalski
     - Felix Exner
     - Jimmy Da Silva
     - Ajit Krisshna N L
     - Muhammad Asif Rana
  -->
  <!-- links -  main serial chain -->
  <!-- base_link serves as the root of the robot's kinematic tree. It follows REP-103
        conventions (i.e., X+ forward, Y+ left, Z+ up).
        Since some kinematic solvers forbid having inertia values attached to a root link, we've
        added the base_link_inertia link that carries the visual, collision and inertia
        information.
    -->
  <link name="arm_0_base_link"/>
  <link name="arm_0_base_link_inertia">
    <visual>
      <origin rpy="0 0 3.141592653589793" xyz="0 0 0"/>
      <geometry>
        <mesh filename="package://mm_3d_model_detached/meshes/ur5e/visual/base.dae"/>
      </geometry>
    </visual>
    <collision>
      <origin rpy="0 0 3.141592653589793" xyz="0 0 0"/>
      <geometry>
        <mesh filename="package://mm_3d_model_detached/meshes/ur5e/collision/base.stl"/>
      </geometry>
    </collision>
    <inertial>
      <mass value="4.0"/>
      <origin rpy="0 0 0" xyz="0 0 0"/>
      <inertia ixx="0.00443333156" ixy="0.0" ixz="0.0" iyy="0.00443333156" iyz="0.0" izz="0.0072"/>
    </inertial>
  </link>
  <link name="arm_0_shoulder_link">
    <visual>
      <origin rpy="0 0 3.141592653589793" xyz="0 0 0"/>
      <geometry>
        <mesh filename="package://mm_3d_model_detached/meshes/ur5e/visual/shoulder.dae"/>
      </geometry>
    </visual>
    <collision>
      <origin rpy="0 0 3.141592653589793" xyz="0 0 0"/>
      <geometry>
        <mesh filename="package://mm_3d_model_detached/meshes/ur5e/collision/shoulder.stl"/>
      </geometry>
    </collision>
    <inertial>
      <mass value="3.761"/>
      <origin rpy="1.570796326794897 0 0" xyz="0.0 -0.00193 -0.02561"/>
      <inertia ixx="0.0070021" ixy="7.3e-07" ixz="-1.053e-05" iyy="0.00648091" iyz="0.00049994" izz="0.00657286"/>
    </inertial>
  </link>
  <link name="arm_0_upper_arm_link">
    <visual>
      <origin rpy="1.5707963267948966 0 -1.5707963267948966" xyz="0 0 0.138"/>
      <geometry>
        <mesh filename="package://mm_3d_model_detached/meshes/ur5e/visual/upperarm.dae"/>
      </geometry>
    </visual>
    <collision>
      <origin rpy="1.5707963267948966 0 -1.5707963267948966" xyz="0 0 0.138"/>
      <geometry>
        <mesh filename="package://mm_3d_model_detached/meshes/ur5e/collision/upperarm.stl"/>
      </geometry>
    </collision>
    <inertial>
      <mass value="8.058"/>
      <origin rpy="0 0 0" xyz="-0.2125 0.0 0.11336"/>
      <inertia ixx="0.01505885" ixy="-5.4e-05" ixz="5.63e-06" iyy="0.33388086" iyz="-1.81e-06" izz="0.33247207"/>
    </inertial>
  </link>
  <link name="arm_0_forearm_link">
    <visual>
      <origin rpy="1.5707963267948966 0 -1.5707963267948966" xyz="0 0 0.007"/>
      <geometry>
        <mesh filename="package://mm_3d_model_detached/meshes/ur5e/visual/forearm.dae"/>
      </geometry>
    </visual>
    <collision>
      <origin rpy="1.5707963267948966 0 -1.5707963267948966" xyz="0 0 0.007"/>
      <geometry>
        <mesh filename="package://mm_3d_model_detached/meshes/ur5e/collision/forearm.stl"/>
      </geometry>
    </collision>
    <inertial>
      <mass value="2.846"/>
      <origin rpy="0 0 0" xyz="-0.2422 0.0 0.0265"/>
      <inertia ixx="0.00399632" ixy="-1.365e-05" ixz="0.00137272" iyy="0.07879254" iyz="-6.6e-06" izz="0.0784851"/>
    </inertial>
  </link>
  <link name="arm_0_wrist_1_link">
    <visual>
      <origin rpy="1.5707963267948966 0 0" xyz="0 0 -0.127"/>
      <geometry>
        <mesh filename="package://mm_3d_model_detached/meshes/ur5e/visual/wrist1.dae"/>
      </geometry>
    </visual>
    <collision>
      <origin rpy="1.5707963267948966 0 0" xyz="0 0 -0.127"/>
      <geometry>
        <mesh filename="package://mm_3d_model_detached/meshes/ur5e/collision/wrist1.stl"/>
      </geometry>
    </collision>
    <inertial>
      <mass value="1.37"/>
      <origin rpy="1.570796326794897 0 0" xyz="0.0 -0.01634 -0.0018"/>
      <inertia ixx="0.00165491" ixy="-2.82e-06" ixz="-4.38e-06" iyy="0.00135962" iyz="0.00010157" izz="0.00126279"/>
    </inertial>
  </link>
  <link name="arm_0_wrist_2_link">
    <visual>
      <origin rpy="0 0 0" xyz="0 0 -0.0997"/>
      <geometry>
        <mesh filename="package://mm_3d_model_detached/meshes/ur5e/visual/wrist2.dae"/>
      </geometry>
    </visual>
    <collision>
      <origin rpy="0 0 0" xyz="0 0 -0.0997"/>
      <geometry>
        <mesh filename="package://mm_3d_model_detached/meshes/ur5e/collision/wrist2.stl"/>
      </geometry>
    </collision>
    <inertial>
      <mass value="1.3"/>
      <origin rpy="-1.570796326794897 0 0" xyz="0.0 0.01634 -0.0018"/>
      <inertia ixx="0.00135617" ixy="-2.74e-06" ixz="4.44e-06" iyy="0.00127827" iyz="-5.048e-05" izz="0.00096614"/>
    </inertial>
  </link>
  <link name="arm_0_wrist_3_link">
    <visual>
      <origin rpy="1.5707963267948966 0 0" xyz="0 0 -0.0989"/>
      <geometry>
        <mesh filename="package://mm_3d_model_detached/meshes/ur5e/visual/wrist3.dae"/>
      </geometry>
    </visual>
    <collision>
      <origin rpy="1.5707963267948966 0 0" xyz="0 0 -0.0989"/>
      <geometry>
        <mesh filename="package://mm_3d_model_detached/meshes/ur5e/collision/wrist3.stl"/>
      </geometry>
    </collision>
    <inertial>
      <mass value="0.365"/>
      <origin rpy="0 0 0" xyz="0.0 0.0 -0.001159"/>
      <inertia ixx="0.00018694" ixy="6e-08" ixz="-1.7e-07" iyy="0.00018908" iyz="-9.2e-07" izz="0.00025756"/>
    </inertial>
  </link>
  <!-- base_joint fixes base_link to the environment -->
  <joint name="arm_0_base_joint" type="fixed">
    <origin rpy="0.0 0.0 -1.5708" xyz="0.2 0.0 0.0"/>
    <parent link="hub_holder_link"/>
    <child link="arm_0_base_link"/>
  </joint>
  <!-- joints - main serial chain -->
  <joint name="arm_0_base_link-base_link_inertia" type="fixed">
    <parent link="arm_0_base_link"/>
    <child link="arm_0_base_link_inertia"/>
    <!-- 'base_link' is REP-103 aligned (so X+ forward), while the internal
           frames of the robot/controller have X+ pointing backwards.
           Use the joint between 'base_link' and 'base_link_inertia' (a dummy
           link/frame) to introduce the necessary rotation over Z (of pi rad).
      -->
    <origin rpy="0 0 3.141592653589793" xyz="0 0 0"/>
  </joint>
  <joint name="arm_0_shoulder_pan_joint" type="revolute">
    <parent link="arm_0_base_link_inertia"/>
    <child link="arm_0_shoulder_link"/>
    <origin rpy="0 0 9.202406954511577e-09" xyz="0 0 0.16257900471087697"/>
    <axis xyz="0 0 1"/>
    <limit effort="150.0" lower="-6.283185307179586" upper="6.283185307179586" velocity="3.141592653589793"/>
    <dynamics damping="0" friction="0"/>
  </joint>
  <joint name="arm_0_shoulder_lift_joint" type="revolute">
    <parent link="arm_0_shoulder_link"/>
    <child link="arm_0_upper_arm_link"/>
    <origin rpy="1.570260341148812 0 -7.07642005437492e-07" xyz="9.972079991894544e-05 0 0"/>
    <axis xyz="0 0 1"/>
    <limit effort="150.0" lower="-6.283185307179586" upper="6.283185307179586" velocity="3.141592653589793"/>
    <dynamics damping="0" friction="0"/>
  </joint>
  <joint name="arm_0_elbow_joint" type="revolute">
    <parent link="arm_0_upper_arm_link"/>
    <child link="arm_0_forearm_link"/>
    <origin rpy="0.001094088938460241 0.0019451043115386814 -1.3912968244365556e-05" xyz="-0.42546441993084994 0 0"/>
    <axis xyz="0 0 1"/>
    <limit effort="150.0" lower="-3.141592653589793" upper="3.141592653589793" velocity="3.141592653589793"/>
    <dynamics damping="0" friction="0"/>
  </joint>
  <joint name="arm_0_wrist_1_joint" type="revolute">
    <parent link="arm_0_forearm_link"/>
    <child link="arm_0_wrist_1_link"/>
    <origin rpy="0.004627697420400071 0.0010631504332256712 1.2397213462962616e-05" xyz="-0.39235527294896877 -0.0006216940735673061 0.1343410294804438"/>
    <axis xyz="0 0 1"/>
    <limit effort="28.0" lower="-6.283185307179586" upper="6.283185307179586" velocity="3.141592653589793"/>
    <dynamics damping="0" friction="0"/>
  </joint>
  <joint name="arm_0_wrist_2_joint" type="revolute">
    <parent link="arm_0_wrist_1_link"/>
    <child link="arm_0_wrist_2_link"/>
    <origin rpy="1.5701220489688144 0 -3.6926181880324663e-07" xyz="0.0001253456377515801 -0.09968569190614744 6.721586181656082e-05"/>
    <axis xyz="0 0 1"/>
    <limit effort="28.0" lower="-6.283185307179586" upper="6.283185307179586" velocity="3.141592653589793"/>
    <dynamics damping="0" friction="0"/>
  </joint>
  <joint name="arm_0_wrist_3_joint" type="revolute">
    <parent link="arm_0_wrist_2_link"/>
    <child link="arm_0_wrist_3_link"/>
    <origin rpy="1.5710940322711167 3.141592653589793 -3.1415926209657723" xyz="4.156906650665715e-05 0.09960516416484248 2.965300370771605e-05"/>
    <axis xyz="0 0 1"/>
    <limit effort="28.0" lower="-6.283185307179586" upper="6.283185307179586" velocity="3.141592653589793"/>
    <dynamics damping="0" friction="0"/>
  </joint>
  <link name="arm_0_ft_frame"/>
  <joint name="arm_0_wrist_3_link-ft_frame" type="fixed">
    <parent link="arm_0_wrist_3_link"/>
    <child link="arm_0_ft_frame"/>
    <origin rpy="3.141592653589793 0 0" xyz="0 0 0"/>
  </joint>
  <!-- ROS-Industrial 'base' frame - base_link to UR 'Base' Coordinates transform -->
  <link name="arm_0_base"/>
  <joint name="arm_0_base_link-base_fixed_joint" type="fixed">
    <!-- Note the rotation over Z of pi radians - as base_link is REP-103
           aligned (i.e., has X+ forward, Y+ left and Z+ up), this is needed
           to correctly align 'base' with the 'Base' coordinate system of
           the UR controller.
      -->
    <origin rpy="0 0 3.141592653589793" xyz="0 0 0"/>
    <parent link="arm_0_base_link"/>
    <child link="arm_0_base"/>
  </joint>
  <!-- ROS-Industrial 'flange' frame - attachment point for EEF models -->
  <link name="arm_0_flange"/>
  <joint name="arm_0_wrist_3-flange" type="fixed">
    <parent link="arm_0_wrist_3_link"/>
    <child link="arm_0_flange"/>
    <origin rpy="0 -1.5707963267948966 -1.5707963267948966" xyz="0 0 0"/>
  </joint>
  <!-- ROS-Industrial 'tool0' frame - all-zeros tool frame -->
  <link name="arm_0_tool0"/>
  <joint name="arm_0_flange-tool0" type="fixed">
    <!-- default toolframe - X+ left, Y+ up, Z+ front -->
    <origin rpy="1.5707963267948966 0 1.5707963267948966" xyz="0 0 0"/>
    <parent link="arm_0_flange"/>
    <child link="arm_0_tool0"/>
  </joint>
  <link name="arm_0_gripper_robotiq_85_base_link">
    <visual>
      <geometry>
        <mesh filename="package://mm_3d_model_detached/meshes/robotiq/visual/robotiq_base.dae"/>
      </geometry>
    </visual>
    <collision>
      <geometry>
        <mesh filename="package://mm_3d_model_detached/meshes/robotiq/collision/robotiq_base.stl"/>
      </geometry>
    </collision>
    <inertial>
      <origin rpy="0 0 0" xyz="0.0 2.274e-05 0.03232288"/>
      <mass value="6.6320197e-01"/>
      <inertia ixx="5.1617816e-04" ixy="2.936e-8" ixz="0.0" iyy="5.8802208e-04" iyz="-3.2296e-7" izz="3.9462776e-04"/>
    </inertial>
  </link>
  <link name="arm_0_gripper_robotiq_85_left_knuckle_link">
    <visual>
      <geometry>
        <mesh filename="package://mm_3d_model_detached/meshes/robotiq/visual/left_knuckle.dae"/>
      </geometry>
    </visual>
    <collision>
      <geometry>
        <mesh filename="package://mm_3d_model_detached/meshes/robotiq/collision/left_knuckle.stl"/>
      </geometry>
    </collision>
    <inertial>
      <origin rpy="0 0 0" xyz="0.01213197 0.0002 -0.00058647"/>
      <mass value="1.384773208e-02"/>
      <inertia ixx="3.5232e-7" ixy="0.0" ixz="1.1744e-7" iyy="2.31944e-6" iyz="0" izz="2.23136e-6"/>
    </inertial>
  </link>
  <link name="arm_0_gripper_robotiq_85_right_knuckle_link">
    <visual>
      <geometry>
        <mesh filename="package://mm_3d_model_detached/meshes/robotiq/visual/right_knuckle.dae"/>
      </geometry>
    </visual>
    <collision>
      <geometry>
        <mesh filename="package://mm_3d_model_detached/meshes/robotiq/collision/right_knuckle.stl"/>
      </geometry>
    </collision>
    <inertial>
      <origin rpy="0 0 0" xyz="-0.01213197 0.0002 -0.00058647"/>
      <mass value="1.384773208e-02"/>
      <inertia ixx="3.5232e-7" ixy="0.0" ixz="-1.1744e-7" iyy="2.31944e-6" iyz="0.0" izz="2.23136e-6"/>
    </inertial>
  </link>
  <link name="arm_0_gripper_robotiq_85_left_finger_link">
    <visual>
      <geometry>
        <mesh filename="package://mm_3d_model_detached/meshes/robotiq/visual/left_finger.dae"/>
      </geometry>
    </visual>
    <collision>
      <geometry>
        <mesh filename="package://mm_3d_model_detached/meshes/robotiq/collision/left_finger.stl"/>
      </geometry>
    </collision>
    <inertial>
      <origin rpy="0 0 0" xyz="0.00346899 -0.00079447 0.01867121"/>
      <mass value="4.260376752e-02"/>
      <inertia ixx="1.385792000000000e-05" ixy="0.0" ixz="-2.17264e-06" iyy="1.183208e-05" iyz="0.0" izz="5.19672e-06"/>
    </inertial>
  </link>
  <link name="arm_0_gripper_robotiq_85_right_finger_link">
    <visual>
      <geometry>
        <mesh filename="package://mm_3d_model_detached/meshes/robotiq/visual/right_finger.dae"/>
      </geometry>
    </visual>
    <collision>
      <geometry>
        <mesh filename="package://mm_3d_model_detached/meshes/robotiq/collision/right_finger.stl"/>
      </geometry>
    </collision>
    <inertial>
      <origin rpy="0 0 0" xyz="-0.00346899 -5.53e-06 0.01867121"/>
      <mass value="4.260376752000000e-02"/>
      <inertia ixx="1.385792e-05" ixy="0.0" ixz="2.17264e-06" iyy="1.183208e-05" iyz="0.0" izz="5.19672e-06"/>
    </inertial>
  </link>
  <link name="arm_0_gripper_robotiq_85_left_inner_knuckle_link">
    <visual>
      <geometry>
        <mesh filename="package://mm_3d_model_detached/meshes/robotiq/visual/left_inner_knuckle.dae"/>
      </geometry>
    </visual>
    <collision>
      <geometry>
        <mesh filename="package://mm_3d_model_detached/meshes/robotiq/collision/left_inner_knuckle.stl"/>
      </geometry>
    </collision>
    <inertial>
      <origin rpy="0 0 0" xyz="0.01897699 0.00015001 0.02247101"/>
      <mass value="2.969376448e-02"/>
      <inertia ixx="9.57136e-06" ixy="0.0" ixz="-3.93424e-06" iyy="8.69056e-06" iyz="0.0" izz="8.19144e-06"/>
    </inertial>
  </link>
  <link name="arm_0_gripper_robotiq_85_right_inner_knuckle_link">
    <visual>
      <geometry>
        <mesh filename="package://mm_3d_model_detached/meshes/robotiq/visual/right_inner_knuckle.dae"/>
      </geometry>
    </visual>
    <collision>
      <geometry>
        <mesh filename="package://mm_3d_model_detached/meshes/robotiq/collision/right_inner_knuckle.stl"/>
      </geometry>
    </collision>
    <inertial>
      <origin rpy="0 0 0" xyz="-0.01926824 5.001e-05 0.02222178"/>
      <mass value="2.969376448e-02"/>
      <inertia ixx="9.42456e-06" ixy="0.0" ixz="3.9636e-06" iyy="8.69056e-06" iyz="0.0" izz="8.33824e-06"/>
    </inertial>
  </link>
  <link name="arm_0_gripper_robotiq_85_left_finger_tip_link">
    <visual>
      <geometry>
        <mesh filename="package://mm_3d_model_detached/meshes/robotiq/visual/left_finger_tip.dae"/>
      </geometry>
    </visual>
    <collision>
      <geometry>
        <mesh filename="package://mm_3d_model_detached/meshes/robotiq/collision/left_finger_tip.stl"/>
      </geometry>
      <surface>
        <friction>
          <ode>
            <mu1>100000.0</mu1>
            <mu2>100000.0</mu2>
          </ode>
        </friction>
        <contact>
          <ode>
            <kp>1e+5</kp>
            <kd>1</kd>
            <soft_cfm>0</soft_cfm>
            <soft_erp>0.2</soft_erp>
            <minDepth>0.002</minDepth>
            <maxVel>0</maxVel>
          </ode>
        </contact>
      </surface>
    </collision>
    <inertial>
      <origin rpy="0 0 0" xyz="-0.01456706 -0.0008 0.01649701"/>
      <mass value="4.268588744e-02"/>
      <inertia ixx="1.048152e-05" ixy="0.0" ixz="3.5232e-6" iyy="1.197888e-05" iyz="0.0" izz="4.22784e-06"/>
    </inertial>
  </link>
  <link name="arm_0_gripper_robotiq_85_right_finger_tip_link">
    <visual>
      <geometry>
        <mesh filename="package://mm_3d_model_detached/meshes/robotiq/visual/right_finger_tip.dae"/>
      </geometry>
    </visual>
    <collision>
      <geometry>
        <mesh filename="package://mm_3d_model_detached/meshes/robotiq/collision/right_finger_tip.stl"/>
      </geometry>
      <surface>
        <friction>
          <ode>
            <mu1>100000.0</mu1>
            <mu2>100000.0</mu2>
          </ode>
        </friction>
        <contact>
          <ode>
            <kp>1e+5</kp>
            <kd>1</kd>
            <soft_cfm>0</soft_cfm>
            <soft_erp>0.2</soft_erp>
            <minDepth>0.002</minDepth>
            <maxVel>0</maxVel>
          </ode>
        </contact>
      </surface>
    </collision>
    <inertial>
      <origin rpy="0 0 0" xyz="0.01456706 5e-05 0.01649701"/>
      <mass value="4.268588744e-02"/>
      <inertia ixx="1.048152e-05" ixy="0.0" ixz="-3.5232e-06" iyy="1.197888e-05" iyz="0.0" izz="4.22784e-06"/>
    </inertial>
  </link>
  <joint name="arm_0_gripper_robotiq_85_base_joint" type="fixed">
    <parent link="arm_0_tool0"/>
    <child link="arm_0_gripper_robotiq_85_base_link"/>
    <origin rpy="0.0 0.0 0.0" xyz="0.0 0.0 0.0"/>
  </joint>
  <joint name="arm_0_gripper_robotiq_85_left_knuckle_joint" type="revolute">
    <parent link="arm_0_gripper_robotiq_85_base_link"/>
    <child link="arm_0_gripper_robotiq_85_left_knuckle_link"/>
    <axis xyz="0 -1 0"/>
    <origin rpy="0 0 0" xyz="0.03060114 0.0 0.05490452"/>
    <limit effort="50" lower="0.0" upper="0.8" velocity="0.5"/>
  </joint>
  <joint name="arm_0_gripper_robotiq_85_right_knuckle_joint" type="revolute">
    <parent link="arm_0_gripper_robotiq_85_base_link"/>
    <child link="arm_0_gripper_robotiq_85_right_knuckle_link"/>
    <axis xyz="0 -1 0"/>
    <origin rpy="0 0 0" xyz="-0.03060114 0.0 0.05490452"/>
    <limit effort="50" lower="-0.8" upper="0.0" velocity="0.5"/>
    <mimic joint="arm_0_gripper_robotiq_85_left_knuckle_joint" multiplier="-1"/>
  </joint>
  <joint name="arm_0_gripper_robotiq_85_left_finger_joint" type="fixed">
    <parent link="arm_0_gripper_robotiq_85_left_knuckle_link"/>
    <child link="arm_0_gripper_robotiq_85_left_finger_link"/>
    <origin rpy="0 0 0" xyz="0.03152616 0.0 -0.00376347"/>
  </joint>
  <joint name="arm_0_gripper_robotiq_85_right_finger_joint" type="fixed">
    <parent link="arm_0_gripper_robotiq_85_right_knuckle_link"/>
    <child link="arm_0_gripper_robotiq_85_right_finger_link"/>
    <origin rpy="0 0 0" xyz="-0.03152616 0.0 -0.00376347"/>
  </joint>
  <joint name="arm_0_gripper_robotiq_85_left_inner_knuckle_joint" type="continuous">
    <parent link="arm_0_gripper_robotiq_85_base_link"/>
    <child link="arm_0_gripper_robotiq_85_left_inner_knuckle_link"/>
    <axis xyz="0 -1 0"/>
    <origin rpy="0 0 0" xyz="0.0127 0.0 0.06142"/>
    <mimic joint="arm_0_gripper_robotiq_85_left_knuckle_joint"/>
  </joint>
  <joint name="arm_0_gripper_robotiq_85_right_inner_knuckle_joint" type="continuous">
    <parent link="arm_0_gripper_robotiq_85_base_link"/>
    <child link="arm_0_gripper_robotiq_85_right_inner_knuckle_link"/>
    <axis xyz="0 -1 0"/>
    <origin rpy="0 0 0" xyz="-0.0127 0.0 0.06142"/>
    <mimic joint="arm_0_gripper_robotiq_85_left_knuckle_joint" multiplier="-1"/>
  </joint>
  <joint name="arm_0_gripper_robotiq_85_left_finger_tip_joint" type="continuous">
    <parent link="arm_0_gripper_robotiq_85_left_finger_link"/>
    <child link="arm_0_gripper_robotiq_85_left_finger_tip_link"/>
    <axis xyz="0 -1 0"/>
    <origin rpy="0 0 0" xyz="0.00563134 0.0 0.04718515"/>
    <mimic joint="arm_0_gripper_robotiq_85_left_knuckle_joint" multiplier="-1"/>
  </joint>
  <joint name="arm_0_gripper_robotiq_85_right_finger_tip_joint" type="continuous">
    <parent link="arm_0_gripper_robotiq_85_right_finger_link"/>
    <child link="arm_0_gripper_robotiq_85_right_finger_tip_link"/>
    <axis xyz="0 -1 0"/>
    <origin rpy="0 0 0" xyz="-0.00563134 0.0 0.04718515"/>
    <mimic joint="arm_0_gripper_robotiq_85_left_knuckle_joint"/>
  </joint>
  <!-- Extras -->
  <!-- Attachment mount link-->
  <link name="mid_mount"/>
  <joint name="mid_mount_joint" type="fixed">
    <parent link="base_link"/>
    <child link="mid_mount"/>
    <origin rpy="0 0 0" xyz="0 0 0.28"/>
  </joint>
  <!-- Colors -->
  <material name="Aluminum">
    <color rgba="0.5 0.5 0.5 1"/>
  </material>
  <material name="Black">
    <color rgba="0.15 0.15 0.15 1.0"/>
  </material>
  <!-- Tower -->
  <link name="lift_plate_link">
    <inertial>
      <origin rpy="0 0 -0.7854" xyz="0 0 0"/>
      <mass value="2"/>
      <inertia ixx="1" ixy="0" ixz="0" iyy="1" iyz="0" izz="1"/>
      <!--ixz="1"-->
    </inertial>
    <visual>
      <origin rpy="0 0 -0.7854" xyz="0 0 0"/>
      <geometry>
        <mesh filename="package://mm_3d_model_detached/meshes/mybotshop/visuals/lift_plate.dae" scale="0.01 0.01 0.01"/>
      </geometry>
      <material name="Aluminum"/>
    </visual>
    <collision>
      <geometry>
        <mesh filename="package://mm_3d_model_detached/meshes/mybotshop/collision/lift_plate.stl" scale="0.01 0.01 0.01"/>
      </geometry>
      <origin rpy="0 0 -0.7854" xyz="0 0 0"/>
    </collision>
  </link>
  <joint name="lift_plate_joint" type="fixed">
    <parent link="mid_mount"/>
    <child link="lift_plate_link"/>
    <origin rpy="0 0 0" xyz="0 0 0"/>
  </joint>
  <link name="orientation_link"/>
  <joint name="orientation_joint" type="fixed">
    <parent link="lift_plate_link"/>
    <child link="orientation_link"/>
    <origin rpy="1.5708 0 4.71239" xyz="0 0 0.33"/>
  </joint>
  <link name="ridgeback_tower_link">
    <inertial>
      <origin rpy="0 0 0" xyz="0 0 0"/>
      <mass value="10"/>
      <inertia ixx="1" ixy="0" ixz="0" iyy="1" iyz="0" izz="1"/>
    </inertial>
    <visual>
      <geometry>
        <mesh filename="package://mm_3d_model_detached/meshes/mybotshop/visuals/short_ridgeback_tower.dae" scale="0.01 0.01 0.01"/>
      </geometry>
      <origin rpy="0 0 0" xyz="0 0 0"/>
      <material name="Aluminum"/>
    </visual>
    <collision>
      <geometry>
        <mesh filename="package://mm_3d_model_detached/meshes/mybotshop/collision/short_ridgeback_tower.stl" scale="0.01 0.01 0.01"/>
      </geometry>
      <origin rpy="0 0 0" xyz="0 0 0"/>
    </collision>
  </link>
  <joint name="ridgeback_tower_joint" type="fixed">
    <parent link="lift_plate_link"/>
    <child link="ridgeback_tower_link"/>
    <origin rpy="0 0 0" xyz="0 0 0.015"/>
    <axis xyz="1 0 0"/>
  </joint>
  <!-- UR5e Control Box -->
  <link name="mmp_ur5e_control_box_link">
    <inertial>
      <origin rpy="0 0 0" xyz="0 0 0"/>
      <mass value="14.0"/>
      <inertia ixx="1" ixy="0" ixz="0" iyy="1" iyz="0" izz="1"/>
      <!--ixz="1"-->
    </inertial>
    <visual>
      <geometry>
        <mesh filename="package://mm_3d_model_detached/meshes/mybotshop/visuals/ur5e_control_box.stl" scale="0.01 0.01 0.01"/>
      </geometry>
      <origin rpy="0 0 0" xyz="0 0 0"/>
      <material name="Aluminum"/>
    </visual>
    <collision>
      <geometry>
        <mesh filename="package://mm_3d_model_detached/meshes/mybotshop/collision/ur5e_control_box.stl" scale="0.01 0.01 0.01"/>
      </geometry>
      <origin rpy="0 0 0" xyz="0 0 0"/>
    </collision>
  </link>
  <joint name="mmp_ur5e_control_box_joint" type="fixed">
    <parent link="ridgeback_tower_link"/>
    <child link="mmp_ur5e_control_box_link"/>
    <origin rpy="0 0 0" xyz="-0.175 0 0.12"/>
    <axis xyz="1 0 0"/>
  </joint>
  <!-- Ouster 3D Lidar -->
  <link name="mmp_ouster_holder_link">
    <inertial>
      <origin rpy="0 0 0" xyz="0 0 0"/>
      <mass value="0.5"/>
      <inertia ixx="1" ixy="0" ixz="0" iyy="1" iyz="0" izz="1"/>
      <!--ixz="1"-->
    </inertial>
    <visual>
      <geometry>
        <mesh filename="package://mm_3d_model_detached/meshes/mybotshop/visuals/mmp_ouster_holder.stl" scale="0.01 0.01 0.01"/>
      </geometry>
      <origin rpy="0 0 0" xyz="0 0 0"/>
      <material name="Black"/>
    </visual>
    <collision>
      <geometry>
        <mesh filename="package://mm_3d_model_detached/meshes/mybotshop/collision/mmp_ouster_holder.stl" scale="0.01 0.01 0.01"/>
      </geometry>
      <origin rpy="0 0 0" xyz="0 0 0"/>
    </collision>
  </link>
  <joint name="mmp_ouster_holder_joint" type="fixed">
    <parent link="ridgeback_tower_link"/>
    <child link="mmp_ouster_holder_link"/>
    <origin rpy="0 0 -1.5708" xyz="0.0585 0 0.81"/>
    <axis xyz="1 0 0"/>
  </joint>
  <joint name="os_sensor_mount_joint" type="fixed">
    <origin rpy="0 0 4.71239" xyz="0 0 0.25"/>
    <!-- 1.5708 -->
    <parent link="mmp_ouster_holder_link"/>
    <child link="os_sensor"/>
  </joint>
  <link name="os_sensor">
    <inertial>
      <mass value="0.33"/>
      <origin rpy="0 0 0" xyz="0 0 0.0365"/>
      <inertia ixx="0.000241148" ixy="0" ixz="0" iyy="0.000241148" iyz="0" izz="0.000264"/>
    </inertial>
    <collision name="base_collision">
      <origin rpy="0 0 0" xyz="0 0 0.0365"/>
      <geometry>
        <cylinder length="0.073" radius="0.04"/>
      </geometry>
    </collision>
    <visual name="base_visual">
      <origin rpy="0 0 1.5707" xyz="0 0 0.0"/>
      <geometry>
        <mesh filename="package://mm_3d_model_detached/meshes/mybotshop/visuals/os_64.dae"/>
      </geometry>
    </visual>
  </link>
  <link name="os_imu"/>
  <link name="os_lidar"/>
  <joint name="os_sensor_imu_link_joint" type="fixed">
    <parent link="os_sensor"/>
    <child link="os_imu"/>
    <origin rpy="0 0 0" xyz="0.006253 -0.011775 0.007645"/>
  </joint>
  <joint name="os_sensor_lidar_link_joint" type="fixed">
    <parent link="os_sensor"/>
    <child link="os_lidar"/>
    <origin rpy="0 0 0" xyz="0.0 0.0 0.03618"/>
  </joint>
  <!-- Lift -->
  <link name="mmp_lift_link">
    <inertial>
      <origin rpy="0 0 0" xyz="0 0 0"/>
      <mass value="2.5"/>
      <inertia ixx="1" ixy="0" ixz="0" iyy="1" iyz="0" izz="1"/>
      <!--ixz="1.0", xx, yy, zz alle = 1-->
    </inertial>
    <visual>
      <geometry>
        <mesh filename="package://mm_3d_model_detached/meshes/mybotshop/visuals/linear_holder_all.stl" scale="0.01 0.01 0.01"/>
      </geometry>
      <origin rpy="0 0 0" xyz="0 0 0"/>
      <material name="Aluminum"/>
    </visual>
    <collision>
      <geometry>
        <mesh filename="package://mm_3d_model_detached/meshes/mybotshop/collision/linear_holder_all.stl" scale="0.01 0.01 0.01"/>
      </geometry>
      <origin rpy="0 0 0" xyz="0 0 0"/>
    </collision>
  </link>
  <joint name="mmp_lift_joint" type="fixed">
    <!--"prismatic"-->
    <parent link="ridgeback_tower_link"/>
    <child link="mmp_lift_link"/>
    <origin rpy="0 0 0" xyz="0.085 0 0"/>
    <axis xyz="0 0 1.0"/>
    <limit effort="0.5" lower="0" upper="0.6" velocity="0.5"/>
  </joint>
  <link name="hub_holder_link">
    <inertial>
      <origin rpy="0 0 0" xyz="0 0 0"/>
      <mass value="2.5"/>
      <inertia ixx="1" ixy="0" ixz="0" iyy="1" iyz="0" izz="1"/>
      <!--ixz="1"-->
    </inertial>
    <visual>
      <geometry>
        <mesh filename="package://mm_3d_model_detached/meshes/mybotshop/visuals/short_hub_holder.dae" scale="0.01 0.01 0.01"/>
      </geometry>
      <origin rpy="0 0 0" xyz="0 0 0"/>
      <material name="Aluminum"/>
    </visual>
    <collision>
      <geometry>
        <mesh filename="package://mm_3d_model_detached/meshes/mybotshop/collision/short_hub_holder.stl" scale="0.01 0.01 0.01"/>
      </geometry>
      <origin rpy="0 0 0" xyz="0 0 0"/>
    </collision>
  </link>
  <joint name="hub_holder_joint" type="fixed">
    <parent link="mmp_lift_link"/>
    <child link="hub_holder_link"/>
    <origin rpy="0 0 0" xyz="0.0 0.0 0"/>
    <axis xyz="1 0 0"/>
  </joint>
  <!---->
  <!-- <ros2_control name="LiftFakeSystem" type="system">
    <hardware>
      <!- By default, set up controllers for simulation. This won't work on real hardware ->
      <plugin>mock_components/GenericSystem</plugin>
      <!-<plugin>lift_controller/LiftHardwareInterface</plugin> ->
    </hardware>
    <joint name="mmp_lift_joint">
      <command_interface name="position"/>
      <state_interface name="position">
        <param name="initial_value">0.05</param>
      </state_interface>
      <state_interface name="velocity">
        <param name="initial_value">0.0</param>
      </state_interface>
    </joint>
  </ros2_control> -->
  <!-- Pan and Tilt holder -->
  <link name="pnt_link">
    <inertial>
      <origin rpy="0 0 0" xyz="0 0 0"/>
      <mass value="0.1"/>
      <inertia ixx="1" ixy="0" ixz="0" iyy="1" iyz="0" izz="1"/>
      <!--ixz="1"-->
    </inertial>
    <visual>
      <geometry>
        <mesh filename="package://mm_3d_model_detached/meshes/mybotshop/visuals/d455_support.dae" scale="0.01 0.01 0.01"/>
      </geometry>
      <origin rpy="0 0 0" xyz="0 0 0"/>
      <material name="Aluminum"/>
    </visual>
    <collision>
      <geometry>
        <mesh filename="package://mm_3d_model_detached/meshes/mybotshop/collision/d455_support.stl" scale="0.01 0.01 0.01"/>
      </geometry>
      <origin rpy="0 0 0" xyz="0 0 0"/>
    </collision>
  </link>
  <joint name="pnt_joint" type="fixed">
    <parent link="hub_holder_link"/>
    <child link="pnt_link"/>
    <origin rpy="0 0 0" xyz="0.0 -0.13 0.0"/>
    <axis xyz="1 0 0"/>
  </joint>
  <!-- Pan and Tilt -->
  <link name="lift_pan_link">
    <inertial>
      <origin rpy="0 0 0" xyz="0 0 0"/>
      <mass value="0.1"/>
      <inertia ixx="1" ixy="0" ixz="0" iyy="1" iyz="0" izz="1"/>
      <!-- ixz="1" -->
    </inertial>
    <visual>
      <geometry>
        <mesh filename="package://mm_3d_model_detached/meshes/mybotshop/visuals/lift_pan_static_motor.stl" scale="0.01 0.01 0.01"/>
      </geometry>
      <origin rpy="0 0 0" xyz="0 0 0"/>
      <material name="Black"/>
    </visual>
    <collision>
      <geometry>
        <mesh filename="package://mm_3d_model_detached/meshes/mybotshop/collision/lift_pan_static_motor.stl" scale="0.01 0.01 0.01"/>
      </geometry>
      <origin rpy="0 0 0" xyz="0 0 0"/>
    </collision>
  </link>
  <joint name="lift_pan_joint" type="fixed">
    <parent link="pnt_link"/>
    <child link="lift_pan_link"/>
    <origin rpy="0 0 0" xyz="0 -0.0825 0.705"/>
    <axis xyz="0 0 1"/>
  </joint>
  <link name="pan_link">
    <inertial>
      <origin rpy="0 0 0" xyz="0 0 0"/>
      <mass value="0.1"/>
      <inertia ixx="1" ixy="0" ixz="0" iyy="1" iyz="0" izz="1"/>
      <!--ixz="1"-->
    </inertial>
    <visual>
      <geometry>
        <mesh filename="package://mm_3d_model_detached/meshes/mybotshop/visuals/lift_pan_mobile_motor.stl" scale="0.01 0.01 0.01"/>
      </geometry>
      <origin rpy="0 0 0" xyz="0 0 0"/>
      <material name="Black"/>
    </visual>
    <collision>
      <geometry>
        <mesh filename="package://mm_3d_model_detached/meshes/mybotshop/collision/lift_pan_mobile_motor.stl" scale="0.01 0.01 0.01"/>
      </geometry>
      <origin rpy="0 0 0" xyz="0 0 0"/>
    </collision>
  </link>
  <joint name="pan_joint" type="fixed">
    <!--"revolute"-->
    <parent link="lift_pan_link"/>
    <child link="pan_link"/>
    <origin rpy="0 0 0" xyz="0.0115 0 0.039"/>
    <axis xyz="0 0 1"/>
    <limit effort="0.5" lower="-1.5708" upper="1.5708" velocity="0.5"/>
  </joint>
  <link name="tilt_link">
    <inertial>
      <origin rpy="0 0 0" xyz="0 0 0"/>
      <mass value="0.1"/>
      <inertia ixx="1" ixy="0" ixz="0" iyy="1" iyz="0" izz="1"/>
      <!--ixz="1"-->
    </inertial>
    <visual>
      <geometry>
        <mesh filename="package://mm_3d_model_detached/meshes/mybotshop/visuals/lift_tilt_unit.stl" scale="0.01 0.01 0.01"/>
      </geometry>
      <origin rpy="0 0 0" xyz="0 0 0"/>
      <material name="Black"/>
    </visual>
    <collision>
      <geometry>
        <mesh filename="package://mm_3d_model_detached/meshes/mybotshop/collision/lift_tilt_unit.stl" scale="0.01 0.01 0.01"/>
      </geometry>
      <origin rpy="0 0 0" xyz="0 0 0"/>
    </collision>
  </link>
  <joint name="tilt_joint" type="fixed">
    <!--"revolute"-->
    <parent link="pan_link"/>
    <child link="tilt_link"/>
    <origin rpy="0 0 0" xyz="0 0 0.038"/>
    <axis xyz="0 1 0"/>
    <limit effort="0.5" lower="-1.5708" upper="1.5708" velocity="0.5"/>
  </joint>
  <!--<ros2_control name="CameraFakeSystem" type="system">
    <hardware>
      <!- By default, set up controllers for simulation. This won't work on real hardware ->
      <!-<plugin>pan_tilt_controller/PanTiltHardwareInterface</plugin>->
      <plugin>mock_components/GenericSystem</plugin>
    </hardware>
    <joint name="pan_joint">
      <command_interface name="position"/>
      <state_interface name="position">
        <param name="initial_value">0.0</param>
      </state_interface>
      <state_interface name="velocity">
        <param name="initial_value">0.0</param>
      </state_interface>
    </joint>
    <joint name="tilt_joint">
      <command_interface name="position"/>
      <state_interface name="position">
        <param name="initial_value">0.0</param>
      </state_interface>
      <state_interface name="velocity">
        <param name="initial_value">0.0</param>
      </state_interface>
    </joint>
  </ros2_control>-->
  <!-- PnT Camera -->
  <material name="aluminum">
    <color rgba="0.5 0.5 0.5 1"/>
  </material>
  <material name="plastic">
    <color rgba="0.1 0.1 0.1 1"/>
  </material>
  <joint name="pan_and_tilt_camera_joint" type="fixed">
    <!-- camera body, with origin at bottom screw mount -->
    <origin rpy="0 0 0" xyz="0 0 0.049"/>
    <parent link="tilt_link"/>
    <child link="pan_and_tilt_camera_bottom_screw_frame"/>
  </joint>
  <link name="pan_and_tilt_camera_bottom_screw_frame"/>
  <joint name="pan_and_tilt_camera_link_joint" type="fixed">
    <origin rpy="0 0 0" xyz="0.011150000000000002 0.0475 0.0145"/>
    <parent link="pan_and_tilt_camera_bottom_screw_frame"/>
    <child link="pan_and_tilt_camera_link"/>
  </joint>
  <link name="pan_and_tilt_camera_link">
    <visual>
      <!-- the mesh origin is at front plate in between the two infrared camera axes -->
      <!-- <origin xyz="${d455_zero_depth_to_glass-d455_cam_depth/2} ${-d455_cam_depth_py} 0" rpy="0 0 0"/> -->
      <origin rpy="1.5707963267948966 0 1.5707963267948966" xyz="0.0046500000000000005 -0.0475 0"/>
      <geometry>
        <!-- <box size="${d455_cam_depth} ${d455_cam_width} ${d455_cam_height}"/> -->
        <mesh filename="package://realsense2_description/meshes/d455.stl" scale="0.001 0.001 0.001"/>
      </geometry>
      <material name="aluminum"/>
    </visual>
    <collision>
      <origin rpy="0 0 0" xyz="-0.00845 -0.0475 0"/>
      <geometry>
        <box size="0.026 0.124 0.029"/>
      </geometry>
    </collision>
    <inertial>
      <!-- The following are not reliable values, and should not be used for modeling -->
      <mass value="0.072"/>
      <origin xyz="0 0 0"/>
      <inertia ixx="0.003881243" ixy="0.0" ixz="0.0" iyy="0.000498940" iyz="0.0" izz="0.003879257"/>
    </inertial>
  </link>
  <joint name="pan_and_tilt_camera_depth_joint" type="fixed">
    <!-- camera depth joints and links -->
    <origin rpy="0 0 0" xyz="0 0 0"/>
    <parent link="pan_and_tilt_camera_link"/>
    <child link="pan_and_tilt_camera_depth_frame"/>
  </joint>
  <link name="pan_and_tilt_camera_depth_frame"/>
  <joint name="pan_and_tilt_camera_depth_optical_joint" type="fixed">
    <origin rpy="-1.5707963267948966 0 -1.5707963267948966" xyz="0 0 0"/>
    <parent link="pan_and_tilt_camera_depth_frame"/>
    <child link="pan_and_tilt_camera_depth_optical_frame"/>
  </joint>
  <link name="pan_and_tilt_camera_depth_optical_frame"/>
  <joint name="pan_and_tilt_camera_infra1_joint" type="fixed">
    <!-- camera left IR joints and links -->
    <origin rpy="0 0 0" xyz="0 0.0 0"/>
    <parent link="pan_and_tilt_camera_link"/>
    <child link="pan_and_tilt_camera_infra1_frame"/>
  </joint>
  <link name="pan_and_tilt_camera_infra1_frame"/>
  <joint name="pan_and_tilt_camera_infra1_optical_joint" type="fixed">
    <origin rpy="-1.5707963267948966 0 -1.5707963267948966" xyz="0 0 0"/>
    <parent link="pan_and_tilt_camera_infra1_frame"/>
    <child link="pan_and_tilt_camera_infra1_optical_frame"/>
  </joint>
  <link name="pan_and_tilt_camera_infra1_optical_frame"/>
  <joint name="pan_and_tilt_camera_infra2_joint" type="fixed">
    <!-- camera right IR joints and links -->
    <origin rpy="0 0 0" xyz="0 -0.095 0"/>
    <parent link="pan_and_tilt_camera_link"/>
    <child link="pan_and_tilt_camera_infra2_frame"/>
  </joint>
  <link name="pan_and_tilt_camera_infra2_frame"/>
  <joint name="pan_and_tilt_camera_infra2_optical_joint" type="fixed">
    <origin rpy="-1.5707963267948966 0 -1.5707963267948966" xyz="0 0 0"/>
    <parent link="pan_and_tilt_camera_infra2_frame"/>
    <child link="pan_and_tilt_camera_infra2_optical_frame"/>
  </joint>
  <link name="pan_and_tilt_camera_infra2_optical_frame"/>
  <joint name="pan_and_tilt_camera_color_joint" type="fixed">
    <!-- camera color joints and links -->
    <origin rpy="0 0 0" xyz="0 -0.059 0"/>
    <parent link="pan_and_tilt_camera_link"/>
    <child link="pan_and_tilt_camera_color_frame"/>
  </joint>
  <link name="pan_and_tilt_camera_color_frame"/>
  <joint name="pan_and_tilt_camera_color_optical_joint" type="fixed">
    <origin rpy="-1.5707963267948966 0 -1.5707963267948966" xyz="0 0 0"/>
    <parent link="pan_and_tilt_camera_color_frame"/>
    <child link="pan_and_tilt_camera_color_optical_frame"/>
  </joint>
  <link name="pan_and_tilt_camera_color_optical_frame"/>
  <link name="pan_and_tilt_camera_accel_frame"/>
  <link name="pan_and_tilt_camera_accel_optical_frame"/>
  <link name="pan_and_tilt_camera_gyro_frame"/>
  <link name="pan_and_tilt_camera_gyro_optical_frame"/>
  <link name="pan_and_tilt_camera_imu_optical_frame"/>
  <joint name="pan_and_tilt_camera_accel_joint" type="fixed">
    <origin rpy="0 0 0" xyz="-0.01602 -0.03022 0.0074"/>
    <parent link="pan_and_tilt_camera_link"/>
    <child link="pan_and_tilt_camera_accel_frame"/>
  </joint>
  <joint name="pan_and_tilt_camera_accel_optical_joint" type="fixed">
    <origin rpy="-1.5707963267948966 0 -1.5707963267948966" xyz="0 0 0"/>
    <parent link="pan_and_tilt_camera_accel_frame"/>
    <child link="pan_and_tilt_camera_accel_optical_frame"/>
  </joint>
  <joint name="pan_and_tilt_camera_gyro_joint" type="fixed">
    <origin rpy="0 0 0" xyz="-0.01602 -0.03022 0.0074"/>
    <parent link="pan_and_tilt_camera_link"/>
    <child link="pan_and_tilt_camera_gyro_frame"/>
  </joint>
  <joint name="pan_and_tilt_camera_gyro_optical_joint" type="fixed">
    <origin rpy="-1.5707963267948966 0 -1.5707963267948966" xyz="0 0 0"/>
    <parent link="pan_and_tilt_camera_gyro_frame"/>
    <child link="pan_and_tilt_camera_gyro_optical_frame"/>
  </joint>
  <joint name="pan_and_tilt_camera_imu_optical_joint" type="fixed">
    <origin rpy="0 0 0" xyz="0 0 0"/>
    <parent link="pan_and_tilt_camera_gyro_optical_frame"/>
    <child link="pan_and_tilt_camera_imu_optical_frame"/>
  </joint>
  <!-- for gazebo ->
  <ros2_control name="pan_controller" type="system">
    <hardware>
      <plugin>ign_ros2_control/IgnitionSystem</plugin>
    </hardware>
    <joint name="pan_joint">
      <command_interface name="position" />
      <command_interface name="velocity" />
      <state_interface name="position"/>
      <state_interface name="velocity"/>
    </joint>
  </ros2_control>
  <ros2_control name="tilt_controller" type="system">
    <hardware>
      <plugin>ign_ros2_control/IgnitionSystem</plugin>
    </hardware>
    <joint name="tilt_joint">
      <command_interface name="position" />
      <command_interface name="velocity" />
      <state_interface name="position"/>
      <state_interface name="velocity"/>
    </joint>
  </ros2_control> -->
  <!--<gazebo reference="pan_and_tilt_camera_color_optical_frame">
    <sensor type="camera" name="realsense_camera">
      <update_rate>30</update_rate>
      <camera>
        <horizontal_fov>1.57</horizontal_fov>
        <image>
          <width>1280</width>
          <height>800</height>
          <format>R8G8B8</format>
        </image>
        <clip>
          <near>0.01</near>
          <far>100</far>
        </clip>
      </camera>
      <plugin name="gazebo_ros_camera" filename="libgazebo_ros_camera.so">
        <always_on>true</always_on>
        <update_rate>30.0</update_rate>
        <camera_name>realsense_camera</camera_name>
        <image_topic_name>camera/image_raw</image_topic_name>
        <camera_info_topic_name>camera/camera_info</camera_info_topic_name>
        <frameName>pan_and_tilt_camera_color_optical_frame</frameName>
      </plugin>
    </sensor>
  </gazebo>-->
  <!--
  <transmission name="tran_2">
    <type>transmission_interface/SimpleTransmission</type>
    <joint name="linear_holder_2_joint">
      <hardwareInterface>hardware_interface/PositionJointInterface</hardwareInterface>
    </joint>
    <actuator name="motor2">
      <hardwareInterface>hardware_interface/PositionJointInterface</hardwareInterface>
      <mechanicalReduction>1</mechanicalReduction>
    </actuator>
  </transmission>
  -->
  <!-- Assigning Materials -->
  <!--
  <gazebo reference="linear_slider_1_link">
    <mu1>10.0</mu1>
    <mu2>10.0</mu2>
    <material>Gazebo/Grey</material>
    <self_collide>0</self_collide>
  </gazebo>
  <gazebo reference="linear_slider_2_link">
    <mu1>10.0</mu1>
    <mu2>10.0</mu2>
    <material>Gazebo/Grey</material>
    <self_collide>0</self_collide>
  </gazebo> 
  ->
  <gazebo reference="mmp_lift_link">
    <mu1>10.0</mu1>
    <mu2>10.0</mu2>
    <material>Gazebo/Black</material>
    <self_collide>0</self_collide>
  </gazebo>
  <!-
  <gazebo reference="linear_holder_2_link">
    <mu1>10.0</mu1>
    <mu2>10.0</mu2>
    <material>Gazebo/Black</material>
    <self_collide>0</self_collide>
  </gazebo>
  <gazebo reference="ouster_stand_link">
    <mu1>10.0</mu1>
    <mu2>10.0</mu2>
    <material>Gazebo/DarkGrey</material>
    <self_collide>0</self_collide>
  </gazebo>
  -->
  <!-- Wirst Camera -->
  <!-- TEST on MORITZ <link name="wrist_camera_holder_link">
    <inertial>
      <origin rpy="0 0 0" xyz="0 0 0"/>
      <mass value="0.1"/>
      <inertia ixx="1" ixy="0" ixz="0" iyy="1" iyz="0" izz="1"/> <!-ixz="1"->
    </inertial>
    <visual>
      <geometry>
        <mesh filename="package://mm_3d_model_detached/meshes/mybotshop/visuals/wrist_camera_holder.stl" scale="0.01 0.01 0.01"/>
      </geometry>
      <origin rpy="0 0 0" xyz="0 0 0"/>
      <material name="Black"/>
    </visual>
    <collision>
      <geometry>
        <mesh filename="package://mm_3d_model_detached/meshes/mybotshop/collision/wrist_camera_holder.stl" scale="0.01 0.01 0.01"/>
      </geometry>
      <origin rpy="0 0 0" xyz="0 0 0"/>
    </collision>
  </link>
  <joint name="wrist_camera_holder_joint" type="fixed">
    <parent link="arm_0_gripper_robotiq_85_base_link"/>  <!-gripper_robotiq_arg2f_base_link-> 
    <child link="wrist_camera_holder_link"/>
    <origin rpy="-1.5708 0 0" xyz="-0.011 -0.05 0.016"/>
    <axis xyz="0 0 1"/>
  </joint>
  <link name="wrist_camera_link">
    <inertial>
      <origin rpy="0 0 0" xyz="0 0 0"/>
      <mass value="0.1"/>
      <inertia ixx="1" ixy="0" ixz="0" iyy="1" iyz="0" izz="1"/> <!-ixz="1"->
    </inertial>
    <visual>
      <geometry>
        <mesh filename="package://mm_3d_model_detached/meshes/mybotshop/visuals/d405.stl" scale="0.01 0.01 0.01"/>
      </geometry>
      <origin rpy="0 0 0" xyz="0 0 0"/>
      <material name="Black"/>
    </visual>
    <collision>
      <geometry>
        <mesh filename="package://mm_3d_model_detached/meshes/mybotshop/collision/d405.stl" scale="0.01 0.01 0.01"/>
      </geometry>
      <origin rpy="0 0 0" xyz="0 0 0"/>
    </collision>
  </link>
  <joint name="wrist_camera_joint" type="fixed">
    <parent link="wrist_camera_holder_link"/>
    <child link="wrist_camera_link"/>
    <origin rpy="1.5708 1.5708 0" xyz="-0.065 0.003 0.05"/>
    <axis xyz="0 0 1"/>
  </joint>
  -->
</robot>
